Workbook

Sheet Unique_Questions
A1: id | B1: source | C1: likely_memorized_classification | D1: question_hebrew | E1: question_english | F1: solution_hebrew | G1: grade_mean | H1: solution_english | I1: subject_labels | J1: task_type_labels | K1: Guy
A2: 2022aa3b | B2: tau exams | C2: 1 | D2: נתון מערך בגודל המכיל n איברים שונים זה מזה. בנוסף, נתון שעבור כל בין 1 ל , האיבר ה-1 בגודלו נמצא באחד המקומות $i-k,i-k+1,...,i+k$ במערך (אם קיימים מקומות כאלו במערך), עבור פרמטר k כלשהו בין 1 ל- . כלומר, מרחק האיבר ממקומו הממוין אינו יותר מ-k. ב. עבור $,k=\sqrt{n}$ הוכיחו חסם של $\Omega(n~log~n)$ למיון המערך | E2: Given an array of size $n$ containing distinct elements. Furthermore, it is given that for every $i$ between $1$ and $n$, the $i$-th smallest element is located in one of the positions $i-k, i-k+1, \ldots, i+k$ in the array (if such positions exist), for some parameter $k$ between $1$ and $n$. In other words, the distance of each element from its position in the sorted order is at most $k$. (b) For $k=\sqrt{n}$, prove a lower bound of $\Omega(n\log n)$ for sorting the array. | F2: נבצע חסם תחתון באמצעות עץ השוואות. נחסום כמה עלים יכולים להיות בכל עץ השוואות. ניקח מערך ממוין ונחלקו לבלוקים בגודל $\sqrt{n}$. נשים לב שאם נסדר כל בלוק בכל פרמוטציה שנבחר המערך שנקבל יקיים את תנאי השאלה. כל מערך כזה צריך להוביל לעלה שונה ולכן נקבל שיש $(\sqrt{n}!)^{\sqrt{n}}$ עלים בכל עץ השוואות. ולכן נדרש לפחות ל $\log((\sqrt{n}!)^{\sqrt{n}})=\Omega(n \log n)$ השוואות | G2: 96.857143 | H2: We prove a lower bound via a comparison tree. We bound how many leaves can be in any comparison tree. Take a sorted array and partition it into blocks of size $\sqrt{n}$. Note that if we arrange each block in any permutation we choose, the resulting array satisfies the problem’s condition. Each such array must lead to a different leaf, and therefore there are $(\sqrt{n}!)^{\sqrt{n}}$ leaves in any comparison tree. Hence at least $\log\big((\sqrt{n}!)^{\sqrt{n}}\big)=\Omega(n \log n)$ comparisons are required. | I2: { "subject_tags": ["Sorting Lower Bound", "Big-Ω", "Upper/Lower Bounds", "Logarithms"] } | J2: { "primary_task_type": "LOWER_BOUND", "secondary_task_types": [] } | K2: OK | L2: =VLOOKUP(A2,Full_Sample_Details!$A$1:$E$205,5,FALSE) -> Given an array of size $n$ containing distinct elements. Furthermore, it is given that for every $i$ between $1$ and $n$, the $i$-th smallest element is located in one of the positions $i-k, i-k+1, \ldots, i+k$ in the array (if such positions exist), for some parameter $k$ between $1$ and $n$. In other words, the distance of each element from its position in the sorted order is at most $k$. (b) For $k=\sqrt{n}$, prove a lower bound of $\Omega(n\log n)$ for sorting the array.
A3: 2022ab3a | B3: tau exams | C3: 1 | D3: נאמר שעץ הוא "נחמד" אם בכל קודקוד בו מתקיימת באופן מקומי תכונת החיפוש. כלומר: אם יש ל-v בן שמאלי אז v.left.key $\le$ v.key ואם יש ל-v בן ימני אז v.key $\le$ v.right.key. ייתכנו מפתחות שווים בעץ. תנו דוגמה לעץ "נחמד" שאינו עץ חיפוש בינארי. | E3: A tree is called ``nice'' if the search property holds locally at every node. That is: if $v$ has a left child then $v.\text{left}.\text{key} \le v.\text{key}$, and if $v$ has a right child then $v.\text{key} \le v.\text{right}.\text{key}$. Equal keys are allowed in the tree. Give an example of a ``nice'' tree that is not a binary search tree. | F3: בדוגמה 1 ל-0 ל-אינסוף ניתן לראות כי מדובר בעץ "נחמד" אך לא עץ חיפוש | G3: 98.714286 | H3: In Example 1, from $0$ to $\infty$, one can see that it is a ``nice'' tree but not a search tree. | I3: { "subject_tags": ["BST"] } | J3: { "primary_task_type": "COUNTEREXAMPLE", "secondary_task_types": [] } | K3: OK | L3: =VLOOKUP(A3,Full_Sample_Details!$A$1:$E$205,5,FALSE) -> A tree is called ``nice'' if the search property holds locally at every node. That is: if $v$ has a left child then $v.\text{left}.\text{key} \le v.\text{key}$, and if $v$ has a right child then $v.\text{key} \le v.\text{right}.\text{key}$. Equal keys are allowed in the tree. Give an example of a ``nice'' tree that is not a binary search tree.
A4: 2022ab3b | B4: tau exams | C4: 0 | D4: נאמר שעץ הוא "נחמד" אם בכל קודקוד בו מתקיימת באופן מקומי תכונת החיפוש. כלומר: אם יש ל-v בן שמאלי אז v.left.key $\le$ v.key ואם יש ל-v בן ימני אז v.key $\le$ v.right.key. ייתכנו מפתחות שווים בעץ. הוכיחו שלא ניתן באופן כללי למיין עץ "נחמד" שהוא שרוך בסיבוכיות טובה יותר $O(n \log n)$. הבהרה: "שרוך" הוא עץ שבו לכל קודקוד יש בן יחיד (או ימני או שמאלי - לא בהכרח כולם לאותו כיוון), פרט לעלה שבקצה השרוך. | E4: We say that a tree is ``nice'' if at every node it locally satisfies the search property; that is, if $v$ has a left child then $v.\mathrm{left}.\mathrm{key} \le v.\mathrm{key}$, and if $v$ has a right child then $v.\mathrm{key} \le v.\mathrm{right}.\mathrm{key}$. Keys may be equal in the tree. Prove that, in general, one cannot sort a ``nice'' tree that is a ``string'' in time complexity better than $O(n \log n)$. Clarification: a ``string'' is a tree in which every node has a single child (either right or left—not necessarily all in the same direction), except for the leaf at the end of the string. | F4: נוכיח חסם תחתון על ידי רדוקציה ממיון: בהינתן קלט $a_0, \dots, a_{n-1}$, נבנה שרוך "נחמד" בגודל n כך שבצומת בעומק i יהיה האיבר $a_i$. עבור כל $1 \le i \le n-1$, אם הערך בצומת ה-i בעומקו קטן מאביו נשים אותו בתור בן שמאלי, אחרת בן ימני. הרדוקציה לוקחת $O(n)$ ולכן לפי חסם תחתון למיון $T(n) = \Omega(n \log n) - O(n) = \Omega(n \log n)$ | G4: 72.714286 | H4: We prove a lower bound by a reduction from sorting: given input $a_0, \dots, a_{n-1}$, we construct a ``nice'' path of size $n$ such that the node at depth $i$ contains the element $a_i$. For every $1 \le i \le n-1$, if the value at the node at depth $i$ is smaller than its parent, we place it as the left child; otherwise, as the right child. The reduction takes $O(n)$, and therefore by the sorting lower bound, $T(n) = \Omega(n \log n) - O(n) = \Omega(n \log n)$. | I4: { "subject_tags": ["Sorting Lower Bound", "Big-O", "Big-Ω", "Upper/Lower Bounds"] } | J4: { "primary_task_type": "LOWER_BOUND", "secondary_task_types": [] } | K4: OK | L4: =VLOOKUP(A4,Full_Sample_Details!$A$1:$E$205,5,FALSE) -> We say that a tree is ``nice'' if at every node it locally satisfies the search property; that is, if $v$ has a left child then $v.\mathrm{left}.\mathrm{key} \le v.\mathrm{key}$, and if $v$ has a right child then $v.\mathrm{key} \le v.\mathrm{right}.\mathrm{key}$. Keys may be equal in the tree. Prove that, in general, one cannot sort a ``nice'' tree that is a ``string'' in time complexity better than $O(n \log n)$. Clarification: a ``string'' is a tree in which every node has a single child (either right or left—not necessarily all in the same direction), except for the leaf at the end of the string.
A5: 2022ab4b | B5: tau exams | C5: 1 | D5: במשחק הנחש (snake) יש לוח של קואורדינטות שלמות במישור $(x,y)$ עבור $|x|,|y|<M$ עבור M גדול כלשהו. על המישור מסתובב נחש, שייצוגו אוסף של n נקודות רצופות במישור הזה, סמוכות זו לזו, מהראש לזנב (לאו דווקא בקו ישר). בכל יחידת זמן, הראש מתקדם לנקודה פנויה סמוכה ("קדימה"/"ימינה"/"שמאלה"), וכל נקודה של הנחש מתקדמת למקום של זו שלפניה. המשחק נמשך כל-עוד הנחש אינו מתנגש בעצמו, או באחד הקירות. הציעו פתרון אחר שבו זמן העדכון ובדיקת ההתנגשויות יהיה $O(\log n)$ במקרה הגרוע. | E5: In the snake game, there is a board consisting of integer coordinates in the plane \((x,y)\) with \(|x|,|y|<M\) for some large \(M\). A snake moves on the plane, represented as a collection of \(n\) consecutive points in this plane, adjacent to each other from head to tail (not necessarily in a straight line). At each unit of time, the head advances to an unoccupied adjacent point (“forward”/“right”/“left”), and each point of the snake moves to the position of the one before it. The game continues as long as the snake does not collide with itself or with one of the walls. Propose an alternative solution in which both the update and the collision checks take \(O(\log n)\) time in the worst case. | F5: פתרון הסעיף הקודם: נחזיק רשימה דו-מקושרת L של חוליות הנחש וטבלת האש H. בכל צעד: 1. נחשב $q = L.getLast()$ (הזנב הישן), נבצע $H.delete(q)$ ו-$L.deleteLast()$. 2. נבדוק אם ראש הנחש החדש p מתנגש בקירות או אם $H.find(p)$ חיובי (התנגשות עצמית); אם כן - סיימנו. 3. אחרת, נבצע $L.insertFirst(p)$ ו-$H.insert(p)$. סיבוכיות: $O(1)$ זמן בתוחלת. הסעיף הנוכחי: הפתרון זהה לסעיף א', אך H יהיה עץ-חיפוש-בינארי מאוזן (כגון עץ AVL) עם יחס-סדר לקסיקוגרפי על נקודות. סיבוכיות: $O(\log n)$ זמן במקרה-הגרוע | G5: 80.142857 | H5: Solution to the previous part: Maintain a doubly linked list $L$ of the snake’s segments and a hash table $H$. At each step: 1. Compute $q = L.getLast()$ (the old tail), perform $H.delete(q)$ and $L.deleteLast()$. 2. Check whether the new head $p$ collides with the walls or whether $H.find(p)$ returns true (self-collision); if so—we terminate. 3. Otherwise, perform $L.insertFirst(p)$ and $H.insert(p)$. Complexity: $O(1)$ expected time. Current part: The solution is identical to part (a), except that $H$ will be a balanced binary search tree (e.g., an AVL tree) with a lexicographic order on points. Complexity: $O(\log n)$ worst-case time. | I5: { "subject_tags": ["Linked Lists", "Hash Tables", "BST", "AVL Trees", "Search", "Insert", "Delete", "Big-O", "Expected Time", "Average vs Worst Case"] } | J5: { "primary_task_type": "DS_DESIGN", "secondary_task_types": ["COMPLEXITY_ANALYSIS"] } | K5: or Algorithm Design | L5: =VLOOKUP(A5,Full_Sample_Details!$A$1:$E$205,5,FALSE) -> In the snake game, there is a board consisting of integer coordinates in the plane \((x,y)\) with \(|x|,|y|<M\) for some large \(M\). A snake moves on the plane, represented as a collection of \(n\) consecutive points in this plane, adjacent to each other from head to tail (not necessarily in a straight line). At each unit of time, the head advances to an unoccupied adjacent point (“forward”/“right”/“left”), and each point of the snake moves to the position of the one before it. The game continues as long as the snake does not collide with itself or with one of the walls. Propose an alternative solution in which both the update and the collision checks take \(O(\log n)\) time in the worst case.
A6: 2023aa2b | B6: tau exams | C6: 1 | D6: נזכר באלגוריתם לפתרון בעיית הבחירה (Selection), שמחלק את האיברים לחמישיות, מוצא חציון בכל חמישייה, מוצא רקורסיבית את חציון החציונים, ומשתמש בו כאיבר ציר (pivot) שמשווה לכולם וממשיך ברקורסיה בחלק המתאים. נניח שבמקום למצוא את חציון החציונים, מוצאים את האחוזון ה-70 שלהם, כלומר האיבר ש- 70% מהחציונים (ערך תחתון) קטנים ממנו. ב. נמשיך להשתמש באחוזון ה-70, אך הפעם מחלקים לשביעיות במקום חמישיות. האם זמן הריצה של האלגוריתם עדיין לינארי? נמקו. | E6: Recall the algorithm for solving the Selection problem, which partitions the elements into groups of five, finds the median in each group, recursively finds the median of the medians, and uses it as a pivot to compare against all elements and continue the recursion in the appropriate part. Suppose that instead of finding the median of the medians, we find their 70th percentile, i.e., the element such that \(70\%\) of the medians (under the lower-value definition) are smaller than it. (b) We continue to use the 70th percentile, but this time we partition into groups of seven instead of five. Is the running time of the algorithm still linear? Justify. | F6: עכשיו בכל שלב ברקורסיה נוריד לפחות $12/70n = 0.3 * 4/7 * n$ איברים. לכן נוסחת הרקורסיה היא $T(n) = T(n/7) + T(58/70n) + O(n)$ מכיוון ש $68/70 = 1/7 + 58/70 < 1$ הפתרון הוא לינארי. | G6: 77.428571 | H6: Now, at each step of the recursion we remove at least $\frac{12}{70} n = 0.3 \cdot \frac{4}{7} \cdot n$ elements. Therefore the recurrence is $T(n) = T(n/7) + T\!\big((58/70)n\big) + O(n)$. Since $\frac{68}{70} = \frac{1}{7} + \frac{58}{70} < 1$, the solution is linear. | I6: { "subject_tags": ["Recurrence Relations", "Divide-and-Conquer", "Big-O"] } | J6: { "primary_task_type": "COMPLEXITY_ANALYSIS", "secondary_task_types": [] } | K6: OK | L6: =VLOOKUP(A6,Full_Sample_Details!$A$1:$E$205,5,FALSE) -> Recall the algorithm for solving the Selection problem, which partitions the elements into groups of five, finds the median in each group, recursively finds the median of the medians, and uses it as a pivot to compare against all elements and continue the recursion in the appropriate part. Suppose that instead of finding the median of the medians, we find their 70th percentile, i.e., the element such that \(70\%\) of the medians (under the lower-value definition) are smaller than it. (b) We continue to use the 70th percentile, but this time we partition into groups of seven instead of five. Is the running time of the algorithm still linear? Justify.
A7: 2023aa3a | B7: tau exams | C7: 1 | D7: תארו מבנה נתונים המתחזק לכל היותר מספרים טבעיים מהתחום $\{1,...,2^{n}\}$, כאשר נתון מראש, ותומך בפעולות הבאות : • (Init(n – אתחול מבנה ריק עם פרמטר . סיבוכיות: (n) • (Insert(x – הכנסת x למבנה, ניתן להניח שאינו קיים. • (Delete(x מחיקת x מהמבנה בהינתן מצביע. • (SameReminder(x - הפעולה מחזירה כמה איברים במבנה זהים ל-x תחת מודולו n. סיבוכיות שלוש הפעולות האחרונות צריכה להיות טובה ביותר במקרה הגרוע. | E7: Describe a data structure that maintains a set of natural numbers from the domain \(\{1,\ldots,2^{n}\}\), where \(n\) is given in advance, and supports the following operations: - Init(\(n\)) — initialize an empty structure with parameter \(n\). Complexity: \(O(n)\). - Insert(\(x\)) — insert \(x\) into the structure; you may assume it does not already exist. - Delete(\(x\)) — delete \(x\) from the structure given a pointer to it. - SameRemainder(\(x\)) — return how many elements in the structure are congruent to \(x\) modulo \(n\). The last three operations should have optimal worst-case complexity. | F7: יש וריאציות רבות לפתרון של תרגיל זה. פתרון אפשרי הוא להחזיק מערך שאריות בגודל n (ידוע מראש) כאשר בכל תא נחזיק רשימה מקושרת עם שדה size. אתחול : הקצאת מערך ואת הרשימות הריקות $O(n)$. (אפשר גם בזמן קבוע כמו שלמדנו.) הכנסה : חישוב אינדקס התא הרלוונטי על ידי $x \pmod n$ (בזמן קבוע) והכנסה לרשימה המקושרת המתאימה תוך עדכון שדה size. מחיקה : בהינתן מצביע למחוק מרשימה נעשה בזמן קבוע, כמו כן אין בעיה לעדכן את שדה ה-size כי אנחנו יכולים לחשב בהינתן x באיזה רשימה הוא נמצא בזמן קבוע או לחלופין לשמור בכל צומת מצביע לראש הרשימה תוך ניצול העובדה שאין איחודים. שארית : בהינתן האיבר ניגש לתא המתאים במערך ונחזיר את שדה הגודל של הרשימה - $O(1)$. | G7: 98.714286 | H7: There are many variations for solving this exercise. One possible solution is to maintain an array of size $n$ (known in advance), indexed by remainders modulo $n$, where each cell holds a linked list with a size field. Initialization: allocate the array and the empty lists — $O(n)$. (This can also be done in constant time as we learned.) Insertion: compute the index via $x \pmod{n}$ (in constant time) and insert into the corresponding linked list while updating the size field. Deletion: given a pointer, deletion from a list is done in constant time; likewise, there is no problem updating the size field because we can compute, given $x$, which list it belongs to in constant time, or alternatively store in each node a pointer to the head of the list, exploiting the fact that there are no unions. Remainder: given the element, access the corresponding array cell and return the list’s size field — $O(1)$. | I7: { "subject_tags": ["Arrays", "Linked Lists", "Hash Tables", "Chaining", "Big-O"] } | J7: { "primary_task_type": "DS_DESIGN", "secondary_task_types": ["COMPLEXITY_ANALYSIS"] } | K7: OK | L7: =VLOOKUP(A7,Full_Sample_Details!$A$1:$E$205,5,FALSE) -> Describe a data structure that maintains a set of natural numbers from the domain \(\{1,\ldots,2^{n}\}\), where \(n\) is given in advance, and supports the following operations: - Init(\(n\)) — initialize an empty structure with parameter \(n\). Complexity: \(O(n)\). - Insert(\(x\)) — insert \(x\) into the structure; you may assume it does not already exist. - Delete(\(x\)) — delete \(x\) from the structure given a pointer to it. - SameRemainder(\(x\)) — return how many elements in the structure are congruent to \(x\) modulo \(n\). The last three operations should have optimal worst-case complexity.
A8: 2023aa3b | B8: tau exams | C8: 1 | D8: תארו מבנה נתונים המתחזק לכל היותר מספרים טבעיים מהתחום $\{1,...,2^{n}\}$, כאשר נתון מראש, ותומך בפעולות הבאות : • (Init(n – אתחול מבנה ריק עם פרמטר . סיבוכיות: (n) • (Insert(x – הכנסת x למבנה, ניתן להניח שאינו קיים. • (Delete(x מחיקת x מהמבנה בהינתן מצביע. • (SameReminder(x - הפעולה מחזירה כמה איברים במבנה זהים ל-x תחת מודולו n. נרצה לשנות את שלוש הפעולות האחרונות בצורה הבאה: • (Insert(x - הכנסת x למבנה, יש לבדוק שאינו קיים. • (Delete x מחיקת x מהמבנה ללא מצביע (בהינתן ערך מספרי). • (SameReminder(x - הפעולה מחזירה כמה איברים במבנה זהים ל- תחת מודולו $2^{\frac{n}{2}}$ תארו מבנה נתונים התומך בפעולות העדכניות בסיבוכיות זמן טובה ביותר בתוחלת. | E8: Describe a data structure that maintains at most $n$ natural numbers from the domain $\{1,\ldots,2^{n}\}$, where $n$ is given in advance, and supports the following operations: • Init$(n)$ — initialize an empty structure with parameter $n$. Complexity: $O(n)$. • Insert$(x)$ — insert $x$ into the structure; you may assume it does not already exist. • Delete$(x)$ — delete $x$ from the structure given a pointer. • SameReminder$(x)$ — return how many elements in the structure are congruent to $x$ modulo $n$. We wish to modify the last three operations as follows: • Insert$(x)$ — insert $x$ into the structure; you must check that it does not already exist. • Delete$(x)$ — delete $x$ from the structure without a pointer (given only its numeric value). • SameReminder$(x)$ — return how many elements in the structure are congruent to $x$ modulo $2^{n/2}$. Describe a data structure that supports the updated operations with the best possible expected running time. | F8: מאתחלים שתי טבלאות hash. מכיוון שהטווח של האיברים ידוע מראש וחסום אפשר להגריל פונקציה ממשפחה אוניברסלית שתקיים את התכונות הרצויות. טבלה אחת תחזיק את האיברים עצמם (מפתח איבר) ואילו טבלה שניה תספור את כמות המופעים שראינו שארית מסוימת (מפתח שארית וערך counter). אתחול : ניצור שתי טבלאות hash בגודל $O(n)$ במימוש chaining. (n ידוע מראש.) הכנסה : בודקים קודם בטבלת האיברים, במידה ונמצא אז נעצור. במידה והאיבר לא קיים אז נכניס לטבלה הראשונה ובנוסף נגדיל את ה counter של הטבלה השניה כאשר נכנס עם המפתח $x \pmod 2^{n/2}$. במידה ולא קיים בטבלה השניה נאתחל עם 1. מחיקה : שוב נבדוק אם קיים. במידה ולא קיים נעצור, אחרת נוציא מהטבלה הראשונה ונחסר 1 מה counter של הטבלה השניה. שארית : ניגש לטבלה השניה עם הערך $x \pmod 2^{n/2}$ ונחזיר את הערך שנמצא שם (אפס במידה והמפתח לא קיים). כל הפעולות חוץ מהאתחול מתבצעות ב-$O(1)$ בתוחלת (וגם את האתחול אפשר). | G8: 98.142857 | H8: Initialize two hash tables. Because the range of elements is known in advance and bounded, we can sample a function from a universal family that satisfies the desired properties. One table stores the elements themselves (key: element), while the second counts how many times we have seen a given residue (key: residue; value: counter). Initialization: Create two hash tables of size $O(n)$ implemented with chaining (with $n$ known in advance). Insertion: First check the element table; if the element is found, stop. If the element is not present, insert it into the first table and also increment the counter in the second table under the key $x \pmod{2^{n/2}}$. If the key does not exist in the second table, initialize it to $1$. Deletion: Again check if the element exists. If it does not, stop; otherwise remove it from the first table and decrement the counter in the second table by $1$. Residue: Query the second table with the key $x \pmod{2^{n/2}}$ and return the value stored there (zero if the key does not exist). All operations except initialization run in expected $O(1)$ time (and the initialization can be as well). | I8: { "subject_tags": ["Hash Tables", "Chaining", "Expected Time", "Big-O"] } | J8: { "primary_task_type": "DS_DESIGN", "secondary_task_types": ["COMPLEXITY_ANALYSIS"] } | K8: OK | L8: =VLOOKUP(A8,Full_Sample_Details!$A$1:$E$205,5,FALSE) -> Describe a data structure that maintains at most $n$ natural numbers from the domain $\{1,\ldots,2^{n}\}$, where $n$ is given in advance, and supports the following operations: • Init$(n)$ — initialize an empty structure with parameter $n$. Complexity: $O(n)$. • Insert$(x)$ — insert $x$ into the structure; you may assume it does not already exist. • Delete$(x)$ — delete $x$ from the structure given a pointer. • SameReminder$(x)$ — return how many elements in the structure are congruent to $x$ modulo $n$. We wish to modify the last three operations as follows: • Insert$(x)$ — insert $x$ into the structure; you must check that it does not already exist. • Delete$(x)$ — delete $x$ from the structure without a pointer (given only its numeric value). • SameReminder$(x)$ — return how many elements in the structure are congruent to $x$ modulo $2^{n/2}$. Describe a data structure that supports the updated operations with the best possible expected running time.
A9: 2023ab1c | B9: tau exams | C9: 0 | D9: קבעו האם הטענות הבאות נכונות או לא נכונות. אם הטענה נכונה, הסבירו בקצרה מדוע. אחרת, הפריכו. ג בערמת מינימום בינארית עם לפחות 128 איברים, האיבר ה- log n n בגודלו יכול להיות בעומק 2. נכון / לא נכון | E9: Determine whether the following statements are true or false. If a statement is true, briefly explain why; otherwise, refute it. (c) In a binary min-heap with at least 128 elements, the $\log n$-th largest element can be at depth 2. True / False. | F9: לא נכון (הקיפו בעיגול) נסמן את הגובה/עומק של העץ ב- $h$. נשים לב שמספר הצמתים בתת עץ של כל צומת בעומק 2 הוא לפחות 2 בחזקת $h-3$ (הרמה ה-$h-1$ חייבת להיות מלאה). מספר הצמתים באופן כללי בעץ קטן שווה מ- 2 בחזקת $h$ (ניתן לחסום קצת יותר טוב אבל אין צורך). לכן לפחות $1/8$ מהצמתים צריכים להיות גדולים מהאיבר ה-$n - \log n$. אבל $n - \log n < n/8$ לכל $n$ גדול מספיק (גדול מ- 128) ולכן זה לא יתכן. | G9: 28.571429 | H9: Incorrect (circle). Let h denote the height/depth of the tree. Note that the number of nodes in the subtree of any node at depth 2 is at least $2^{h-3}$ (the level $h-1$ must be full). The total number of nodes in the tree is at most $2^{h}$ (one can bound this slightly better, but it is unnecessary). Therefore at least $1/8$ of the nodes must be greater than the $(n-\log n)$-th element. But $n-\log n < n/8$ for all sufficiently large $n$ (greater than $128$), and therefore this is impossible. | I9: { "subject_tags": ["Binary Heaps", "Upper/Lower Bounds", "Logarithms", "Growth Rates"] } | J9: { "primary_task_type": "MCQ_TF", "secondary_task_types": ["PROOF_CORRECTNESS"] } | K9: OK. Secondary: also CounterExample | L9: =VLOOKUP(A9,Full_Sample_Details!$A$1:$E$205,5,FALSE) -> Determine whether the following statements are true or false. If a statement is true, briefly explain why; otherwise, refute it. (c) In a binary min-heap with at least 128 elements, the $\log n$-th largest element can be at depth 2. True / False.
A10: 2024aa1a | B10: tau exams | C10: 1 | D10: ADT להלן ה "תור משוכלל" השומר אוסף של איברים בצורת FIFO (first in - first out): enqueue(x) - הכנסת x לסוף התור. dequeue() - החזרת האיבר שבראש התור ומחיקתו מהתור. retrieve(i) – החזרת האיבר ה-i בתור (i=1 הוא הראשון בתור, i=n הוא האחרון בתור, כאשר n היא כמות האיברים בתור). א. הציעו מבנה נתונים המממש את ה ADT בזמן אמורטייזד O(1) לכל אחת משלוש הפעולות. הערה: בשני הסעיפים סיבוכיות המקום צריכה להיות לינארית בכמות האיברים שבמבנה. | E10: Consider the following ADT, an “enhanced queue” that maintains a collection of elements in FIFO (first in–first out) order: - \texttt{enqueue(x)} — insert \(x\) at the end of the queue. - \texttt{dequeue()} — return the element at the front of the queue and delete it from the queue. - \texttt{retrieve(i)} — return the \(i\)-th element in the queue (\(i=1\) is the first in the queue, \(i=n\) is the last in the queue, where \(n\) is the number of elements in the queue). (a) Propose a data structure that implements the ADT with amortized \(O(1)\) time for each of the three operations. Note: In both parts, the space complexity should be linear in the number of elements stored in the structure. | F10: מבנה הנתונים: מערך מעגלי שנעשה לו doubling. נשמור שדה גלובאלי $M$ שמציין את גודל המערך הנוכחי, שדה גלובאלי $n$ שמציין את מספר האיברים במבנה ושדה גלובאלי last שיצביע לסוף התור. מימוש הפעולות: enqueue(x) – ראשית, במידה ו $n = M$, נעתיק את האיברים למערך בגודל 2M החל מאינדקס 1 ונשנה את last ל $M+1$. שנית, נכניס את x למקום last ולאחר מכן נגדיל ב1 את n ואת last. dequeue() – האיבר שיש להחזיר נמצא באינדקס $(last - n)\%M$. נקטיין את n ב-1. אם $n = M/4$ אז נעתיק את האיברים למערך בגודל $M/2$ החל מאינדקס 0 ונשנה את last ל $M/4 + 1$. Retrieve(i) – נחזיר את האיבר במקום ה- $(last - n + i - 1)\%M$. מקום: מתקיים $M/4 \le n \le M$ ולכן כמות המקום שמבנה הנתונים צורך היא ליניארית במספר האיברים שמורים במבנה. ניתוח סיבוכיות: כל הפעולות מתבצעות בזמן אמורטייזד $O(1)$. ניתן להוכיח באמצעות פונקציית הפוטנציאל $\phi(M,n) = \begin{cases} 2n - M, & n \ge M/2 \\ M/2 - n, & n \le M/2 \end{cases}$. | G10: 94.571429 | H10: Data structure: a circular array with doubling. We maintain a global variable $M$ indicating the current array size, a global variable $n$ indicating the number of elements in the structure, and a global variable $last$ that points to the end of the queue. Implementation of the operations: - enqueue$(x)$: First, if $n = M$, copy the elements to an array of size $2M$ starting from index $1$ and set $last$ to $M+1$. Second, insert $x$ at position $last$, then increment $n$ and $last$ by $1$. - dequeue(): The element to return is at index $(last - n)\%M$. Decrease $n$ by $1$. If $n = M/4$, copy the elements to an array of size $M/2$ starting from index $0$ and set $last$ to $M/4 + 1$. - Retrieve$(i)$: Return the element at position $(last - n + i - 1)\%M$. Space: We maintain $M/4 \le n \le M$, hence the space used by the data structure is linear in the number of elements stored in the structure. Complexity analysis: All operations run in amortized $O(1)$ time. This can be proved using the potential function $\phi(M,n) = \begin{cases} 2n - M, & n \ge M/2 \\ M/2 - n, & n \le M/2 \end{cases}$. | I10: { "subject_tags": ["Arrays", "Dynamic Arrays", "Potential Method", "Big-O"] } | J10: { "primary_task_type": "DS_DESIGN", "secondary_task_types": [] } | K10: OK | L10: =VLOOKUP(A10,Full_Sample_Details!$A$1:$E$205,5,FALSE) -> Consider the following ADT, an “enhanced queue” that maintains a collection of elements in FIFO (first in–first out) order: - \texttt{enqueue(x)} — insert \(x\) at the end of the queue. - \texttt{dequeue()} — return the element at the front of the queue and delete it from the queue. - \texttt{retrieve(i)} — return the \(i\)-th element in the queue (\(i=1\) is the first in the queue, \(i=n\) is the last in the queue, where \(n\) is the number of elements in the queue). (a) Propose a data structure that implements the ADT with amortized \(O(1)\) time for each of the three operations. Note: In both parts, the space complexity should be linear in the number of elements stored in the structure.
A11: 2024aa3a | B11: tau exams | C11: 1 | D11: להלן ADT לתחזוקת איברים עם מפתחות מתחום סדור. ל ADT ישנו פרמטר "פוקוס" שערכו הדיפולטיבי הוא 1 שיוגדר בהמשך. כל זמני הריצה בשאלה הם WC. insert(key, value) – הכנסת איבר עם מפתח key וערך value. delete(key) – מחיקת האיבר עם מפתח key. setFocus(f) – קובע את פרמטר ה "פוקוס" של ה ADT להיות f. נתון ש- 1 ≤ f ≤ n. select(i) - מחזיר את האיבר ה-i בגודלו. א. הציעו מבנה נתונים המממש את ה ADT בזמן O(log n) עבור insert, delete, setFocus ובזמן O(log(|i-f|+2)) עבור select(i), כאשר f מציין את פרמטר ה "פוקוס" ו-n את כמות האיברים במבנה. | E11: The following ADT maintains elements with keys from an ordered domain. The ADT has a parameter ``focus'' whose default value is 1 (as defined below). All running times in the question are worst-case. \texttt{insert(key, value)} — insert an element with key $key$ and value $value$. \texttt{delete(key)} — delete the element with key $key$. \texttt{setFocus(f)} — set the ADT’s ``focus'' parameter to $f$. It is given that $1 \le f \le n$. \texttt{select(i)} — return the $i$-th smallest element. (a) Propose a data structure that implements the ADT with time $O(\log n)$ for \texttt{insert}, \texttt{delete}, and \texttt{setFocus}, and time $O(\log(\lvert i - f\rvert + 2))$ for \texttt{select(i)}, where $f$ denotes the ``focus'' parameter and $n$ is the number of elements in the structure. | F11: מבנה הנתונים – 2 עצי AVL. אחד עבור $f$ המפתחות הקטנים בעץ ואחד עבור $n-f$ המפתחות הגדולים. בהתחלה (לפני שאילתת focus) יהיה לנו עץ AVL בודד שהוא ריק. העצים ישמרו שדה size בשביל שאילתות select. בנוסף העץ עם האיברים הקטנים ישמור מצביע למקסימום והעץ השני ישמור מצביע למינימום. בנוסף יהיה לנו משתנה גלובלית $f$ שישמור את ה-"focus". Insert(key, val) – במידה ו $f$ עוד לא אותחל אז נכניס רגיל לעץ AVL הבודד של מבנה הנתונים. אחרת. נשווה את key למקסימום של $f$ האיברים הקטנים ולפי זה נדע לאיזה עץ להכניס את key. במידה והכנסנו את key לעץ של המפתחות הקטנים אז נמחק שם את המקסימום ונעבירו לעץ של המפתחות הגדולים. delete(key) - במידה ו $f$ עוד לא אותחל אז נמחק רגיל מעץ AVL הבודד של מבנה הנתונים. אחרת. נשווה את key למקסימום של $f$ האיברים הקטנים ולפי זה נדע מאיזה עץ למחוק את key. במידה ומחקנו את key מהעץ של המפתחות הקטנים אז נמחק את המינימום בעץ של המפתחות הגדולים ונעבירו לעץ של המפתחות הקטנים. setFocus(f) – נמזג את עצי ה-AVL ונעשה להם split באיבר מדרגה $f$. נעדכן את משתנה ה-focus הגלובאלי שלנו ל $f$. select(i) – נבצע select באמצעות המצביע למינימום/מקסימום של העץ המתאים. סיבוכיות – נובע מסיבוכיות AVL finger tree. | G11: 52.714286 | H11: Data structure: two AVL trees. One stores the $f$ smallest keys and one stores the $n-f$ largest keys. Initially (before any focus query) we have a single empty AVL tree. The trees maintain a size field for select queries. In addition, the tree with the smaller elements keeps a pointer to its maximum, and the other tree keeps a pointer to its minimum. We also keep a global variable $f$ that stores the “focus.” Insert(key, val) — If $f$ has not yet been initialized, insert as usual into the single AVL tree of the data structure. Otherwise, compare key to the maximum of the tree of the $f$ smallest keys to decide into which tree to insert key. If we inserted key into the small-keys tree, delete its maximum there and move it to the large-keys tree. delete(key) — If $f$ has not yet been initialized, delete as usual from the single AVL tree of the data structure. Otherwise, compare key to the maximum of the tree of the $f$ smallest keys to decide from which tree to delete key. If we deleted key from the small-keys tree, delete the minimum in the large-keys tree and move it to the small-keys tree. setFocus($f$) — Merge the AVL trees and split them at the element of rank $f$. Update the global focus variable to $f$. select($i$) — Perform select using the pointer to the minimum/maximum of the appropriate tree. Complexity: follows from the complexity of an AVL finger tree. | I11: { "subject_tags": ["AVL Trees", "Order-Statistic Trees", "Insert", "Delete", "Selection Problem"] } | J11: { "primary_task_type": "DS_DESIGN", "secondary_task_types": [] } | K11: OK | L11: =VLOOKUP(A11,Full_Sample_Details!$A$1:$E$205,5,FALSE) -> The following ADT maintains elements with keys from an ordered domain. The ADT has a parameter ``focus'' whose default value is 1 (as defined below). All running times in the question are worst-case. \texttt{insert(key, value)} — insert an element with key $key$ and value $value$. \texttt{delete(key)} — delete the element with key $key$. \texttt{setFocus(f)} — set the ADT’s ``focus'' parameter to $f$. It is given that $1 \le f \le n$. \texttt{select(i)} — return the $i$-th smallest element. (a) Propose a data structure that implements the ADT with time $O(\log n)$ for \texttt{insert}, \texttt{delete}, and \texttt{setFocus}, and time $O(\log(\lvert i - f\rvert + 2))$ for \texttt{select(i)}, where $f$ denotes the ``focus'' parameter and $n$ is the number of elements in the structure.
A12: 2003ba9 | B12: tau exams | C12: 1 | D12: נתון מערך A המכיל n מספרים שלמים. בהינתן מספרx המופיע ב A, נגדיר את הריבוי שלx במערך A בתור מספר המופעים של x ב-A. רוצים לייצר מערך ממוין B בגודל n, שיכיל את הריבוי של כל אחד מהמספרים המופיעים ב A. הציעו אלגוריתם שפותר את הבעיה בתוחלת זמן הטובה ביותר. | E12: Given an array \(A\) containing \(n\) integers. For a number \(x\) that appears in \(A\), define the multiplicity of \(x\) in the array \(A\) as the number of occurrences of \(x\) in \(A\). We wish to produce a sorted array \(B\) of size \(n\), which contains the multiplicity of each of the numbers appearing in \(A\). Propose an algorithm that solves the problem in the best possible expected time. | F12: תאור האלגוריתם: נכניס את איברי הקבוצה לטבלת Hash בגודל (n). ערכים חוזרים יוחזקו על ידי מונה (כלומר בפעולת ההכנסה, נעבור על כל הרשימה בתא אליו הגענו, ורק אם הערך לא נמצא נוסיף איבר חדש לרשימה, עם מונה מאותחל לאחד). בסוף הכנסת כל האיברים, נעבור על הטבלא ונחלץ את כל הריבויים. כל הערכים הנ"ל הם שלמים בתחום 1 עד n לכן ניתן למינם בעזרת CountSort. הוכחת זמן ריצה : הכנסה לטבלה – סה"כ צפוי (ממוצע) O(n) חילוץ ריבויים מהטבלה O(n) CountSort O(n) סה"כ צפוי O(n) | G12: 84.714286 | H12: Algorithm description: Insert the elements into a hash table of size \(n\). Repeated values are maintained by a counter (i.e., during insertion we traverse the entire list in the bucket reached, and only if the value is not found do we add a new item to the list with its counter initialized to one). After all elements are inserted, traverse the table and extract all the multiplicities. All these values are integers in the range \(1\) to \(n\), so they can be sorted using CountSort. Proof of running time: Insertion into the table — total expected (average) \(O(n)\) Extracting multiplicities from the table — \(O(n)\) CountSort — \(O(n)\) Total expected \(O(n)\). | I12: { "subject_tags": ["Hash Tables", "Chaining", "Non-Comparison Sorting", "Expected Time", "Big-O"] } | J12: { "primary_task_type": "ALG_DESIGN", "secondary_task_types": ["COMPLEXITY_ANALYSIS"] } | K12: OK | L12: =VLOOKUP(A12,Full_Sample_Details!$A$1:$E$205,5,FALSE) -> Given an array \(A\) containing \(n\) integers. For a number \(x\) that appears in \(A\), define the multiplicity of \(x\) in the array \(A\) as the number of occurrences of \(x\) in \(A\). We wish to produce a sorted array \(B\) of size \(n\), which contains the multiplicity of each of the numbers appearing in \(A\). Propose an algorithm that solves the problem in the best possible expected time.
A13: 2004aa4 | B13: tau exams | C13: 1 | D13: נתונה טבלת Hash פתוחה בגודל B, שבה התנגשויות בכל תא נפתרות על ידי רשימה מקושרת. הטבלה תומכת בפעולות Insert, Delete, Find. עבור סדרת פעולות באורך N, המורכבת ממספר שווה של כל אחת מהפעולות הנ"ל (N/3 מכל סוג), ומתחילה עם מבנה ריק, זמן Amortized לפעולה בודדת במבנה הוא: (תזכורת: זמן Amortized לפעולה הוא זמן W.C. של סידרה של N פעולות, חלקי N). א. θ(1) ב. θ(B) ג. θ(N) ד. θ(B^2) ה. θ(N^2) ו. אף אחת מהנ"ל. | E13: Given an open-hashing hash table of size \(B\), where collisions in each bucket are resolved by a linked list. The table supports the operations Insert, Delete, and Find. For a sequence of operations of length \(N\), consisting of an equal number of each of the above operations (\(N/3\) of each), and starting with an empty structure, the amortized time per single operation in the structure is: (Reminder: the amortized time per operation is the worst-case time of a sequence of \(N\) operations, divided by \(N\).) a. \(\Theta(1)\) b. \(\Theta(B)\) c. \(\Theta(N)\) d. \(\Theta(B^2)\) e. \(\Theta(N^2)\) f. None of the above. | F13: ג. כל פעולה במבנה לוקחת w.c. O(N) ולכן זהו חסם על זמן Amortized.. סידרה שמתחילה N/3 פעולות Insert שבה כל האיברים נופלים נופלים לאותו תא, וכל פעולות החיפוש כושלות אחרי סריקת הרשימה הארוכה, תיקח Θ(N2). | G13: 95.571429 | H13: (c) Every operation in the data structure takes worst-case $O(N)$, and therefore this is an upper bound on the amortized time. A sequence that begins with $\frac{N}{3}$ Insert operations in which all the elements fall into the same bucket, and in which all search operations fail only after scanning the long list, will take $\Theta(N^2)$. | I13: { "subject_tags": ["Hash Tables", "Chaining", "Big-O", "Big-Θ", "Upper/Lower Bounds", "Search", "Insert"] } | J13: { "primary_task_type": "MCQ_TF", "secondary_task_types": [] } | K13: OK. Secondary: AMORTIZED_ANALYSIS | L13: =VLOOKUP(A13,Full_Sample_Details!$A$1:$E$205,5,FALSE) -> Given an open-hashing hash table of size \(B\), where collisions in each bucket are resolved by a linked list. The table supports the operations Insert, Delete, and Find. For a sequence of operations of length \(N\), consisting of an equal number of each of the above operations (\(N/3\) of each), and starting with an empty structure, the amortized time per single operation in the structure is: (Reminder: the amortized time per operation is the worst-case time of a sequence of \(N\) operations, divided by \(N\).) a. \(\Theta(1)\) b. \(\Theta(B)\) c. \(\Theta(N)\) d. \(\Theta(B^2)\) e. \(\Theta(N^2)\) f. None of the above.
... A30: 2017ab1-a | B30: tau exams | C30: 1 | D30: נתון מערך של ח מספרים שלמים בין 0 ל-2 בחזקת n. נתון שכל מספר במערך הוא כפולה של ערך עליון של 2 בחזקת N, חלקי N בחזקת שלוש. הציעו אלגוריתם למיון המערך. | E30: Given an array of $k$ integers between $0$ and $2^n$. It is given that every number in the array is a multiple of $\left\lceil \frac{2^N}{N^3} \right\rceil$. Propose an algorithm to sort the array. | F30: נחלק כל מספר ב-(ערך עליון של 2 בחזקת N, חלקי N בחזקת שלוש). כעת איברי המערך בתחום [0, n^3] וניתן למיינם באמצעות O(n) .radix sort. | G30: 70.428571 | H30: Divide each number by $\left\lceil \frac{2^N}{N^3} \right\rceil$. Now the array elements lie in $[0, n^3]$ and can be sorted using an $O(n)$ radix sort. | I30: { "subject_tags": ["Non-Comparison Sorting", "Big-O"] } | J30: { "primary_task_type": "ALG_DESIGN", "secondary_task_types": [] } | K30: OK | L30: =VLOOKUP(A30,Full_Sample_Details!$A$1:$E$205,5,FALSE) -> Given an array of $k$ integers between $0$ and $2^n$. It is given that every number in the array is a multiple of $\left\lceil \frac{2^N}{N^3} \right\rceil$. Propose an algorithm to sort the array.

Sheet Full_Sample_Details
A1: id | B1: source | C1: likely_memorized_classification | D1: question_hebrew | E1: question_english | F1: solution_hebrew | G1: grade_mean | H1: solution_english | I1: subject_labels | J1: task_type_labels | K1: rep_id | L1: model_solution | M1: grade | N1: answer_grade | O1: mean_grade_class
A2: 2004aa5 | B2: tau exams | C2: 0 | D2: אם log(f(n)) = θ(log(g(n))) אז בהכרח: א. f(n) = θ(g(n + 1)) ב. f(n) = θ(g(n/2)) ג. f(n) = θ(g(n^0.5)) ד. א + ב ה. א + ב + ג ו. אף אחת מהנ"ל | E2: If $\log(f(n)) = \Theta(\log(g(n)))$ then necessarily: A. $f(n) = \Theta(g(n+1))$ B. $f(n) = \Theta(g(n/2))$ C. $f(n) = \Theta(g(n^{0.5}))$ D. A + B E. A + B + C F. None of the above | F2: ו. דוגמה נגדית: f(n) = n! , g(n) = nn | G2: 78.285714 | H2: vi. Counterexample: $f(n) = n!, \quad g(n) = n^{n}$ | I2: { "subject_tags": ["Growth Rates"] } | J2: { "primary_task_type": "MCQ_TF", "secondary_task_types": [] } | K2: 2004aa5_0 | L2: Exponentiating c₁ log g(n) ≤ log f(n) ≤ c₂ log g(n) gives g(n)^{c₁} ≤ f(n) ≤ g(n)^{c₂}; thus f(n) is Θ of a power of g(n), not necessarily of g at n+1, n/2, or n^{0.5}. Counter-example: let g(n)=2^n and f(n)=4^n; then log f(n)=2 log g(n) so log f=Θ(log g), but f(n)/g(n+1)=2^{n}/2→∞, f(n)/g(n/2)=2^{3n/2}→∞, and f(n)/g(n^{0.5})=4^n/2^{√n}→∞. Therefore none of A, B, or C is guaranteed. Answer: F. | M2: 100 | N2: Grade: 100 Justification: The student correctly reasons from log f = Θ(log g) to f being Θ of a power of g and provides a concrete counterexample g(n)=2^n, f(n)=4^n showing that none of A, B, or C is guaranteed. Their calculations explicitly demonstrate that f is not Θ of g(n+1), g(n/2), or g(n^{0.5}). This fully aligns with the official solution’s requirement of a counterexample (which gives a different but also valid pair, f(n)=n!, g(n)=n^n). The answer is accurate, clear, and complete. | O2: 0
A3: 2004aa5 | B3: tau exams | C3: 0 | D3: אם log(f(n)) = θ(log(g(n))) אז בהכרח: א. f(n) = θ(g(n + 1)) ב. f(n) = θ(g(n/2)) ג. f(n) = θ(g(n^0.5)) ד. א + ב ה. א + ב + ג ו. אף אחת מהנ"ל | E3: If $\log(f(n)) = \Theta(\log(g(n)))$ then necessarily: A. $f(n) = \Theta(g(n+1))$ B. $f(n) = \Theta(g(n/2))$ C. $f(n) = \Theta(g(n^{0.5}))$ D. A + B E. A + B + C F. None of the above | F3: ו. דוגמה נגדית: f(n) = n! , g(n) = nn | G3: 78.285714 | H3: vi. Counterexample: $f(n) = n!, \quad g(n) = n^{n}$ | I3: { "subject_tags": ["Growth Rates"] } | J3: { "primary_task_type": "MCQ_TF", "secondary_task_types": [] } | K3: 2004aa5_1 | L3: Because log f(n) = Θ(log g(n)) only implies g(n)^α ≤ f(n) ≤ g(n)^β for some positive constants α, β, f(n) can differ from g(n) by an arbitrary fixed power. For example, let g(n) = n and f(n) = n²; then log f(n) = 2 log n = Θ(log g(n)), yet f(n) ≠ Θ(g(n+1)), Θ(g(n/2)), or Θ(g(n^{0.5})). Hence none of the listed relations must hold. Answer: F. | M3: 98 | N3: Grade: 98 Justification: The official solution requires providing a counterexample showing the statement is false. The student correctly concludes the statement is false and supplies a valid counterexample: g(n)=n and f(n)=n^2 satisfy log f(n) = Θ(log g(n)), yet f(n) is not Θ of g evaluated at any of the listed argument modifications (n+1, n/2, n^{0.5}). Their general reasoning that log equivalence only constrains f between constant powers of g is essentially correct under standard assumptions (functions ≥ 1 eventually). The answer is clear and accurate. A tiny deduction for not explicitly checking assumptions (e.g., eventual positivity) or aligning with the exact counterexample in the official solution, but the provided counterexample is fully valid. | O3: 0
A4: 2004aa5 | B4: tau exams | C4: 0 | D4: אם log(f(n)) = θ(log(g(n))) אז בהכרח: א. f(n) = θ(g(n + 1)) ב. f(n) = θ(g(n/2)) ג. f(n) = θ(g(n^0.5)) ד. א + ב ה. א + ב + ג ו. אף אחת מהנ"ל | E4: If $\log(f(n)) = \Theta(\log(g(n)))$ then necessarily: A. $f(n) = \Theta(g(n+1))$ B. $f(n) = \Theta(g(n/2))$ C. $f(n) = \Theta(g(n^{0.5}))$ D. A + B E. A + B + C F. None of the above | F4: ו. דוגמה נגדית: f(n) = n! , g(n) = nn | G4: 78.285714 | H4: vi. Counterexample: $f(n) = n!, \quad g(n) = n^{n}$ | I4: { "subject_tags": ["Growth Rates"] } | J4: { "primary_task_type": "MCQ_TF", "secondary_task_types": [] } | K4: 2004aa5_2 | L4: F. None of the above. | M4: 0 | N4: Grade: 0 Justification: The official solution selects option vi and provides a specific counterexample f(n) = n! and g(n) = n^n. The student answered “None of the above,” which directly contradicts the correct choice and provided no counterexample or explanation. The required components (correct option and illustrative counterexample) are entirely missing. | O4: 0
A5: 2004aa5 | B5: tau exams | C5: 0 | D5: אם log(f(n)) = θ(log(g(n))) אז בהכרח: א. f(n) = θ(g(n + 1)) ב. f(n) = θ(g(n/2)) ג. f(n) = θ(g(n^0.5)) ד. א + ב ה. א + ב + ג ו. אף אחת מהנ"ל | E5: If $\log(f(n)) = \Theta(\log(g(n)))$ then necessarily: A. $f(n) = \Theta(g(n+1))$ B. $f(n) = \Theta(g(n/2))$ C. $f(n) = \Theta(g(n^{0.5}))$ D. A + B E. A + B + C F. None of the above | F5: ו. דוגמה נגדית: f(n) = n! , g(n) = nn | G5: 78.285714 | H5: vi. Counterexample: $f(n) = n!, \quad g(n) = n^{n}$ | I5: { "subject_tags": ["Growth Rates"] } | J5: { "primary_task_type": "MCQ_TF", "secondary_task_types": [] } | K5: 2004aa5_3 | L5: F. None of the above. Example: let g(n)=2ⁿ and f(n)=2²ⁿ; then log f(n)=2n log 2=Θ(log g(n)), yet f(n)/g(n+1)=2^{n-1}, f(n)/g(n/2)=2^{3n/2}, and f(n)/g(n^{0.5})=2^{2n-√n}, all of which diverge. Thus A, B, and C fail in general. | M5: 100 | N5: Grade: 100 Justification: The task was to refute the proposed statements by providing a counterexample where log f(n) = Θ(log g(n)) but the claims (A, B, C) fail. The student correctly chose f(n) = 2^{2n} and g(n) = 2^n, established log f(n) = 2 log g(n), and explicitly showed that the relevant ratios f(n)/g(n+1), f(n)/g(n/2), and f(n)/g(n^{0.5}) diverge, thereby invalidating A, B, and C. This matches the spirit of the official solution, which also provides a counterexample (with different functions). The reasoning is accurate, complete, and clear. | O5: 0
A6: 2004aa5 | B6: tau exams | C6: 0 | D6: אם log(f(n)) = θ(log(g(n))) אז בהכרח: א. f(n) = θ(g(n + 1)) ב. f(n) = θ(g(n/2)) ג. f(n) = θ(g(n^0.5)) ד. א + ב ה. א + ב + ג ו. אף אחת מהנ"ל | E6: If $\log(f(n)) = \Theta(\log(g(n)))$ then necessarily: A. $f(n) = \Theta(g(n+1))$ B. $f(n) = \Theta(g(n/2))$ C. $f(n) = \Theta(g(n^{0.5}))$ D. A + B E. A + B + C F. None of the above | F6: ו. דוגמה נגדית: f(n) = n! , g(n) = nn | G6: 78.285714 | H6: vi. Counterexample: $f(n) = n!, \quad g(n) = n^{n}$ | I6: { "subject_tags": ["Growth Rates"] } | J6: { "primary_task_type": "MCQ_TF", "secondary_task_types": [] } | K6: 2004aa5_4 | L6: F | M6: 80 | N6: Grade: 80 Justification: The student answered “F,” which matches the official solution’s conclusion (the statement is false). However, the official solution provides a counterexample (f(n) = n!, g(n) = n^n) to justify the answer, while the student gave no reasoning or evidence. The lack of explanation/justification reduces the score despite the correct final verdict. | O6: 0
A7: 2004aa5 | B7: tau exams | C7: 0 | D7: אם log(f(n)) = θ(log(g(n))) אז בהכרח: א. f(n) = θ(g(n + 1)) ב. f(n) = θ(g(n/2)) ג. f(n) = θ(g(n^0.5)) ד. א + ב ה. א + ב + ג ו. אף אחת מהנ"ל | E7: If $\log(f(n)) = \Theta(\log(g(n)))$ then necessarily: A. $f(n) = \Theta(g(n+1))$ B. $f(n) = \Theta(g(n/2))$ C. $f(n) = \Theta(g(n^{0.5}))$ D. A + B E. A + B + C F. None of the above | F7: ו. דוגמה נגדית: f(n) = n! , g(n) = nn | G7: 78.285714 | H7: vi. Counterexample: $f(n) = n!, \quad g(n) = n^{n}$ | I7: { "subject_tags": ["Growth Rates"] } | J7: { "primary_task_type": "MCQ_TF", "secondary_task_types": [] } | K7: 2004aa5_5 | L7: Since log f(n) = Θ(log g(n)) implies only that f(n) = g(n)^{Θ(1)}, no specific shift or scaling of the input argument is forced. Choosing, for example, g(n) = n and f(n) = n² gives log f(n) = 2 log n = Θ(log n) = Θ(log g(n)), yet • f(n) = n² ≠ Θ(g(n+1)) = Θ(n), • f(n) = n² ≠ Θ(g(n/2)) = Θ(n), and • f(n) = n² ≠ Θ(g(n^{0.5})) = Θ(√n). Thus none of the listed relations must hold in general. Answer: F. | M7: 100 | N7: Grade: 100 Justification: The statement is false, and the student correctly identifies this and provides a valid counterexample. Their example f(n) = n^2 and g(n) = n satisfies log f(n) = Θ(log g(n)) but fails all the proposed relations involving input shifts/scalings, which directly refutes the claim. The reasoning that log f = Θ(log g) only implies f is between constant powers of g (i.e., f = g^{Θ(1)}) is accurate in the standard setting and supports why no specific input transformation must follow. The answer is clear, correct, and complete, even though it uses a different counterexample than the official solution. | O7: 0
A8: 2004aa5 | B8: tau exams | C8: 0 | D8: אם log(f(n)) = θ(log(g(n))) אז בהכרח: א. f(n) = θ(g(n + 1)) ב. f(n) = θ(g(n/2)) ג. f(n) = θ(g(n^0.5)) ד. א + ב ה. א + ב + ג ו. אף אחת מהנ"ל | E8: If $\log(f(n)) = \Theta(\log(g(n)))$ then necessarily: A. $f(n) = \Theta(g(n+1))$ B. $f(n) = \Theta(g(n/2))$ C. $f(n) = \Theta(g(n^{0.5}))$ D. A + B E. A + B + C F. None of the above | F8: ו. דוגמה נגדית: f(n) = n! , g(n) = nn | G8: 78.285714 | H8: vi. Counterexample: $f(n) = n!, \quad g(n) = n^{n}$ | I8: { "subject_tags": ["Growth Rates"] } | J8: { "primary_task_type": "MCQ_TF", "secondary_task_types": [] } | K8: 2004aa5_6 | L8: F. Because log-equivalence only constrains f(n) to lie between constant powers of g(n), no fixed shift or scaling of g’s argument (like n+1, n/2, or n^0.5) is guaranteed to match f asymptotically in every case. | M8: 70 | N8: Grade: 70 Justification: The student correctly identifies the statement as false and gives a generally accurate rationale that log-equivalence only bounds f between constant powers of g, which does not guarantee a match via argument shifts/scalings. However, the official solution requires an explicit counterexample (e.g., f(n) = n!, g(n) = n^n), which the student did not provide. The explanation is also somewhat hand-wavy and includes an imprecise example (“n^0.5” as a “scaling” of the argument), rather than a clear, rigorous disproof. | O8: 0
A9: 2016aa2-b | B9: tau exams | C9: 0 | D9: בהמשך לסעיף הקודם, הפעם נתון שכל המפתחות שלמים ומהתחום [1,n^3]. תאר/י מבנה נתונים שניתן לבנות אותו בזמן Worst case O(n) (בהינתן n זוגות המפתחות) ותומך בפעולה SearchAll בזמן Worst case O(log(n)). | E9: Continuing from the previous part, this time it is given that all keys are integers in the range $[1, n^3]$. Describe a data structure that can be built in worst-case $O(n)$ time (given $n$ pairs of keys) and supports the operation SearchAll in worst-case $O(\log n)$ time. | F9: נמיין ע"י sort radix את כל הזוגות לפי המפתח השמאלי. נאתחל מערך בגודל n כך שתא i במערך יחזיק רשימה של כל הזוגות שהמפתח השמאלי שלהם הוא האיבר ה – i בגודלו מבין המפתחות השמאליים. | G9: 63 | H9: Sort all pairs by the left key using radix sort. Initialize an array of size $n$ such that the $i$-th cell of the array holds a list of all pairs whose left key is the $i$-th largest among the left keys. | I9: { "subject_tags": ["Non-Comparison Sorting", "Arrays"] } | J9: { "primary_task_type": "DS_DESIGN", "secondary_task_types": [] } | K9: 2016aa2-b_0 | L9: Store the structure in three contiguous arrays. 1) Copy the 2n individual keys into an array and radix-sort them in base n (3 passes, Θ(n) time), then scan once to build the sorted list K[1..m] (m ≤ 2n) of distinct keys and give every key k its rank r(k) in this list. 2) Make an array deg[1..m] (initially 0), scan the n pairs once and increment deg[r(x)] and deg[r(y)] for every pair (x,y). 3) Prefix-sum deg to obtain start[1..m+1]; after this, the future partners of key k will occupy List[start[r(k)] … start[r(k)+1) ). 4) Scan the pairs a second time and place each partner into its slot in List, advancing the current pointer inside the interval; this finishes all adjacency lists. The data kept is K, start and List (total Θ(n) words). SearchAll(q): binary-search K for q (Θ(log n)); if absent return ∅, otherwise let i be its position and output List[start[i] … start[i+1) ). Building needs the three linear scans over at most 2n items plus two scans over the n pairs, i.e. Θ(n) worst-case time, and the search costs Θ(log n) worst-case time, satisfying the requirements. | M9: 87 | N9: Grade: 87 Justification: The student presents a clear, detailed, and correct linear-time build using coordinate compression, degree counting, prefix sums, and contiguous adjacency lists, with O(log n) query via binary search. This matches the spirit of the official solution (grouping by sorted keys after a radix sort) and meets the required time and space bounds. However, there are a few mismatches: (1) the student builds adjacency lists for both sides of each pair, so SearchAll(q) returns all partners of q regardless of whether q is a left or right key, whereas the official solution indexes only by the left key; this could produce extraneous results if only left-key queries are intended. (2) The student returns partners rather than explicit pairs, which is fine if one can reconstruct (q, partner) but deviates from the official phrasing. (3) The “3 passes in base n” is an unnecessary assumption (though consistent with typical constraints). Overall, the approach is correct and efficient, but slightly overgeneralized relative to the official solution’s left-key indexing. | O9: 0
A10: 2016aa2-b | B10: tau exams | C10: 0 | D10: בהמשך לסעיף הקודם, הפעם נתון שכל המפתחות שלמים ומהתחום [1,n^3]. תאר/י מבנה נתונים שניתן לבנות אותו בזמן Worst case O(n) (בהינתן n זוגות המפתחות) ותומך בפעולה SearchAll בזמן Worst case O(log(n)). | E10: Continuing from the previous part, this time it is given that all keys are integers in the range $[1, n^3]$. Describe a data structure that can be built in worst-case $O(n)$ time (given $n$ pairs of keys) and supports the operation SearchAll in worst-case $O(\log n)$ time. | F10: נמיין ע"י sort radix את כל הזוגות לפי המפתח השמאלי. נאתחל מערך בגודל n כך שתא i במערך יחזיק רשימה של כל הזוגות שהמפתח השמאלי שלהם הוא האיבר ה – i בגודלו מבין המפתחות השמאליים. | G10: 63 | H10: Sort all pairs by the left key using radix sort. Initialize an array of size $n$ such that the $i$-th cell of the array holds a list of all pairs whose left key is the $i$-th largest among the left keys. | I10: { "subject_tags": ["Non-Comparison Sorting", "Arrays"] } | J10: { "primary_task_type": "DS_DESIGN", "secondary_task_types": [] } | K10: 2016aa2-b_1 | L10: Radix-sort the n pairs lexicographically (three passes of base-n counting/radix sort suffice because every key is in [1, n³] and fits in 3 log n bits), obtaining a sorted array in Θ(n) worst-case time. From this array build a perfectly balanced binary-search tree by recursively choosing the middle element as parent; this bottom-up construction costs another Θ(n) time and Θ(n) space. While scanning the sorted array, group identical pairs and store only one copy in the tree node together with a linked list (or array segment) that contains all duplicates of that pair. A SearchAll(x,y) query is a standard BST search on the lexicographic key (x,y); it touches at most ⌈log₂n⌉ nodes, hence runs in Θ(log n) worst-case time. If the key is present, the pointer kept in its node gives direct access to all copies, which can then be enumerated without affecting the asymptotic bound. Thus the data structure is built in Θ(n) worst-case time, occupies Θ(n) space, and answers every SearchAll query in Θ(log n) worst-case time. | M10: 25 | N10: Grade: 25 Justification: - The official solution requires: (1) radix sort by the left key only; (2) build an array of size n where the i-th entry stores all pairs whose left key is the i-th largest among left keys (grouping by left key). - The student instead sorts pairs lexicographically (by both keys), then builds a balanced BST over full pairs and only groups exact duplicate pairs, not all pairs sharing the same left key. This misses the required grouping by left key and the array-of-lists structure indexed by left-key rank. - The stated “three passes” of base-n radix sort to sort pairs lexicographically is incorrect; with base n, each key in [1, n^3] needs 3 passes, so a pair would need 6 passes (or 2 passes with base n^3). - The proposed BST and SearchAll(x, y) query do not match the official construction or its intended organization; the student’s query semantics differ and are unnecessary. - Some partial credit for recognizing linear-time radix sorting and linear-time construction, but the core data structure and grouping criterion are wrong. | O10: 0
A11: 2016aa2-b | B11: tau exams | C11: 0 | D11: בהמשך לסעיף הקודם, הפעם נתון שכל המפתחות שלמים ומהתחום [1,n^3]. תאר/י מבנה נתונים שניתן לבנות אותו בזמן Worst case O(n) (בהינתן n זוגות המפתחות) ותומך בפעולה SearchAll בזמן Worst case O(log(n)). | E11: Continuing from the previous part, this time it is given that all keys are integers in the range $[1, n^3]$. Describe a data structure that can be built in worst-case $O(n)$ time (given $n$ pairs of keys) and supports the operation SearchAll in worst-case $O(\log n)$ time. | F11: נמיין ע"י sort radix את כל הזוגות לפי המפתח השמאלי. נאתחל מערך בגודל n כך שתא i במערך יחזיק רשימה של כל הזוגות שהמפתח השמאלי שלהם הוא האיבר ה – i בגודלו מבין המפתחות השמאליים. | G11: 63 | H11: Sort all pairs by the left key using radix sort. Initialize an array of size $n$ such that the $i$-th cell of the array holds a list of all pairs whose left key is the $i$-th largest among the left keys. | I11: { "subject_tags": ["Non-Comparison Sorting", "Arrays"] } | J11: { "primary_task_type": "DS_DESIGN", "secondary_task_types": [] } | K11: 2016aa2-b_2 | L11: 1. Radix–sort the n pairs (k₁,k₂) lexicographically in three passes, using base n; because every key is in [1,n³], each pass costs Θ(n), so the whole sorting phase is Θ(n). 2. In one left-to-right scan of the sorted list, group consecutive pairs having the same first component k₁ and, for each distinct k₁, record the indices (l,r) of its block in the array. 3. Build a perfectly balanced binary-search tree on the ordered list of distinct first keys; each node stores its key and the corresponding block indices (l,r). 4. This tree construction from a sorted list is linear, hence total preprocessing time and space are Θ(n). 5. SearchAll(a) descends the balanced tree to locate key a in O(log n) worst-case time. 6. If a is not present the query ends; otherwise the stored indices (l,r) immediately identify the contiguous sub-array holding every pair whose first component is a, which can be reported in O(output) additional time. 7. If the operation must locate a specific pair (a,b), perform a second binary search on k₂ inside that sub-array, adding at most another O(log n) factor, so the entire query is still worst-case O(log n). 8. Thus the data structure is built in worst-case Θ(n) time and answers every SearchAll query in worst-case Θ(log n) time (plus the unavoidable output size). | M11: 90 | N11: Grade: 90 Justification: - Main components in the official solution: (1) radix sort by the left key in linear time; (2) organize results into an array of size n where the i-th cell holds all pairs with the i-th largest left key (i.e., contiguous buckets per left key). - Student included: radix sorting, grouping contiguous blocks by left key, and a lookup structure to find the block for a given key. Complexity claims are correct (linear preprocessing, O(log n) lookup plus O(output)). - Issues: - The student says to radix-sort lexicographically in three passes with base n. That is inaccurate: three passes suffice to sort a single key in [1, n^3]; lexicographic sort of (k1, k2) would need twice that (or at least 3 passes for k1 only, which is what’s needed). Sorting by both keys is unnecessary. - They did not literally create the array-of-lists described in the official solution; instead they maintain (l, r) indices and a balanced BST over distinct first keys. This is functionally equivalent and acceptable but deviates from the exact data structure described. - Overall, the approach is correct and complete, with one notable technical misstatement about the radix-sort passes and a slight structural deviation. | O11: 0
